ERROR:root:Got exception on main handler
Traceback (most recent call last):
  File "C:\Users\Zoomy\Desktop\Thesis\Chess-Engine_Reinforcement-Learning\src\main.py", line 171, in <module>
    main.run()
  File "C:\Users\Zoomy\Desktop\Thesis\Chess-Engine_Reinforcement-Learning\src\main.py", line 52, in run
    self._event_handler(self.simulate)
  File "C:\Users\Zoomy\Desktop\Thesis\Chess-Engine_Reinforcement-Learning\src\main.py", line 70, in _event_handler
    self.game.simulate_game()
  File "C:\Users\Zoomy\Desktop\Thesis\Chess-Engine_Reinforcement-Learning\src\game.py", line 96, in simulate_game
    self.move_piece(int(mv[3]),int(mv[4]))
  File "C:\Users\Zoomy\Desktop\Thesis\Chess-Engine_Reinforcement-Learning\src\game.py", line 142, in move_piece
    legalities = current_piece.legals(self.board)
TypeError: 'list' object is not callable
